<mujoco model="panda_reach">
  <compiler angle="radian" meshdir="assets" autolimits="true"/>
  <option integrator="implicitfast" impratio="10" timestep="0.002"/>
  <visual>
    <global offwidth="1280" offheight="720"/>
  </visual>

  <default>
    <default class="panda">
      <material specular="0.5" shininess="0.25"/>
      <joint armature="0.1" damping="1" axis="0 0 1" range="-2.8973 2.8973"/>
      <general dyntype="none" biastype="affine" ctrlrange="-2.8973 2.8973" forcerange="-87 87"/>
      <default class="panda/visual">
        <geom type="mesh" contype="0" conaffinity="0" group="2"/>
      </default>
      <default class="panda/collision">
        <geom type="mesh" group="3"/>
      </default>
      <site size="0.001" rgba="0.5 0.5 0.5 0.3" group="4"/>
    </default>
    <default class="obstacle">
      <geom contype="1" conaffinity="1" rgba="0.8 0.2 0.2 0.8"/>
    </default>
  </default>

  <asset>
    <material class="panda" name="white" rgba="1 1 1 1"/>
    <material class="panda" name="off_white" rgba="0.901961 0.921569 0.929412 1"/>
    <material class="panda" name="dark_grey" rgba="0.25 0.25 0.25 1"/>
    <material class="panda" name="green" rgba="0 1 0 1"/>
    <material class="panda" name="light_blue" rgba="0.039216 0.541176 0.780392 1"/>
    <mesh name="link0_c" file="link0.stl"/>
    <mesh name="link1_c" file="link1.stl"/>
    <mesh name="link2_c" file="link2.stl"/>
    <mesh name="link3_c" file="link3.stl"/>
    <mesh name="link4_c" file="link4.stl"/>
    <mesh name="link5_c0" file="link5_collision_0.obj"/>
    <mesh name="link5_c1" file="link5_collision_1.obj"/>
    <mesh name="link5_c2" file="link5_collision_2.obj"/>
    <mesh name="link6_c" file="link6.stl"/>
    <mesh name="link7_c" file="link7.stl"/>
    <mesh file="link0_0.obj"/><mesh file="link0_1.obj"/><mesh file="link0_2.obj"/>
    <mesh file="link0_3.obj"/><mesh file="link0_4.obj"/><mesh file="link0_5.obj"/>
    <mesh file="link0_7.obj"/><mesh file="link0_8.obj"/><mesh file="link0_9.obj"/>
    <mesh file="link0_10.obj"/><mesh file="link0_11.obj"/>
    <mesh file="link1.obj"/><mesh file="link2.obj"/>
    <mesh file="link3_0.obj"/><mesh file="link3_1.obj"/><mesh file="link3_2.obj"/><mesh file="link3_3.obj"/>
    <mesh file="link4_0.obj"/><mesh file="link4_1.obj"/><mesh file="link4_2.obj"/><mesh file="link4_3.obj"/>
    <mesh file="link5_0.obj"/><mesh file="link5_1.obj"/><mesh file="link5_2.obj"/>
    <mesh file="link6_0.obj"/><mesh file="link6_1.obj"/><mesh file="link6_2.obj"/><mesh file="link6_3.obj"/>
    <mesh file="link6_4.obj"/><mesh file="link6_5.obj"/><mesh file="link6_6.obj"/><mesh file="link6_7.obj"/>
    <mesh file="link6_8.obj"/><mesh file="link6_9.obj"/><mesh file="link6_10.obj"/><mesh file="link6_11.obj"/>
    <mesh file="link6_12.obj"/><mesh file="link6_13.obj"/><mesh file="link6_14.obj"/><mesh file="link6_15.obj"/>
    <mesh file="link6_16.obj"/>
    <mesh file="link7_0.obj"/><mesh file="link7_1.obj"/><mesh file="link7_2.obj"/><mesh file="link7_3.obj"/>
    <mesh file="link7_4.obj"/><mesh file="link7_5.obj"/><mesh file="link7_6.obj"/><mesh file="link7_7.obj"/>
  </asset>

  <worldbody>
    <light pos="0 0 2" dir="0 0 -1" diffuse="1 1 1"/>
    <geom name="table" type="plane" pos="0 0 0" size="2 2 0.05" rgba="0.7 0.7 0.7 1" contype="1" conaffinity="1"/>
    <site name="goal_site" pos="0.5 0 0.3" size="0.025" rgba="0 1 0 0.5"/>

    <body name="link0" pos="0 0 0">
      <inertial mass="0.629769" pos="-0.041018 -0.00014 0.049974"
        fullinertia="0.00315 0.00388 0.004285 8.29e-7 0.00015 8.29e-7"/>
      <geom mesh="link0_0" material="off_white" class="panda/visual"/>
      <geom mesh="link0_1" material="dark_grey" class="panda/visual"/>
      <geom mesh="link0_2" material="dark_grey" class="panda/visual"/>
      <geom mesh="link0_3" material="dark_grey" class="panda/visual"/>
      <geom mesh="link0_4" material="dark_grey" class="panda/visual"/>
      <geom mesh="link0_5" material="dark_grey" class="panda/visual"/>
      <geom mesh="link0_7" material="dark_grey" class="panda/visual"/>
      <geom mesh="link0_8" material="dark_grey" class="panda/visual"/>
      <geom mesh="link0_9" material="dark_grey" class="panda/visual"/>
      <geom mesh="link0_10" material="dark_grey" class="panda/visual"/>
      <geom mesh="link0_11" material="white" class="panda/visual"/>
      <geom mesh="link0_c" class="panda/collision"/>
      <body name="link1" pos="0 0 0.333">
        <inertial mass="4.970684" pos="0.003875 0.002081 0.047095"
          fullinertia="0.70337 0.70661 0.009117 0.000139 0.006772 0.019169"/>
        <joint name="joint1" range="-2.8973 2.8973"/>
        <geom mesh="link1" material="white" class="panda/visual"/>
        <geom mesh="link1_c" class="panda/collision"/>
        <body name="link2" quat="1 -1 0 0">
          <inertial mass="0.646926" pos="-0.003141 -0.02872 0.003495"
            fullinertia="0.007962 0.02811 0.025995 0.000133 0.000458 0.001953"/>
          <joint name="joint2" range="-1.7628 1.7628"/>
          <geom mesh="link2" material="white" class="panda/visual"/>
          <geom mesh="link2_c" class="panda/collision"/>
          <body name="link3" pos="0 -0.316 0" quat="1 1 0 0">
            <inertial mass="3.228604" pos="0.027518 0.039252 -0.066502"
              fullinertia="0.037242 0.036155 0.01083 -0.004761 0.011396 0.012805"/>
            <joint name="joint3" range="-2.8973 2.8973"/>
            <geom mesh="link3_0" material="white" class="panda/visual"/>
            <geom mesh="link3_1" material="white" class="panda/visual"/>
            <geom mesh="link3_2" material="white" class="panda/visual"/>
            <geom mesh="link3_3" material="dark_grey" class="panda/visual"/>
            <geom mesh="link3_c" class="panda/collision"/>
            <body name="link4" pos="0.0825 0 0" quat="1 1 0 0">
              <inertial mass="3.587895" pos="-0.05317 0.104419 0.027454"
                fullinertia="0.025853 0.019552 0.028323 0.007796 -0.001332 0.008641"/>
              <joint name="joint4" range="-3.0718 -0.0698"/>
              <geom mesh="link4_0" material="white" class="panda/visual"/>
              <geom mesh="link4_1" material="white" class="panda/visual"/>
              <geom mesh="link4_2" material="dark_grey" class="panda/visual"/>
              <geom mesh="link4_3" material="white" class="panda/visual"/>
              <geom mesh="link4_c" class="panda/collision"/>
              <body name="link5" pos="-0.0825 0.384 0" quat="1 -1 0 0">
                <inertial mass="1.225946" pos="-0.011953 0.041065 -0.038437"
                  fullinertia="0.035549 0.029474 0.008627 -0.002117 -0.004037 0.000229"/>
                <joint name="joint5" range="-2.8973 2.8973"/>
                <geom mesh="link5_0" material="dark_grey" class="panda/visual"/>
                <geom mesh="link5_1" material="white" class="panda/visual"/>
                <geom mesh="link5_2" material="white" class="panda/visual"/>
                <geom mesh="link5_c0" class="panda/collision"/>
                <geom mesh="link5_c1" class="panda/collision"/>
                <geom mesh="link5_c2" class="panda/collision"/>
                <body name="link6" quat="1 1 0 0">
                  <inertial mass="1.666555" pos="0.060149 -0.014117 -0.010517"
                    fullinertia="0.001964 0.004354 0.005433 0.000109 -0.001158 0.000341"/>
                  <joint name="joint6" range="-0.0175 3.7525"/>
                  <geom mesh="link6_c" class="panda/collision"/>
                  <body name="link7" pos="0.088 0 0" quat="1 1 0 0">
                    <inertial mass="0.735522" pos="0.010517 -0.004252 0.061597"
                      fullinertia="0.012516 0.010027 0.004815 -0.000428 -0.001196 -0.000741"/>
                    <joint name="joint7" range="-2.8973 2.8973"/>
                    <geom mesh="link7_c" class="panda/collision"/>
                    <body name="attachment" pos="0 0 0.107" quat="0.3826834 0 0 0.9238795">
                      <site name="attachment_site" size="0.01" rgba="1 0 0 0.5"/>
                    </body>
                  </body>
                </body>
              </body>
            </body>
          </body>
        </body>
      </body>
    </body>

    <!-- 8 obstacle slots (§3.2 MAX_OBS=8) -->
    <geom name="obs_0" class="obstacle" type="box" pos="5 5 5" size="0.05 0.05 0.05"/>
    <geom name="obs_1" class="obstacle" type="box" pos="5 5 5" size="0.05 0.05 0.05"/>
    <geom name="obs_2" class="obstacle" type="box" pos="5 5 5" size="0.05 0.05 0.05"/>
    <geom name="obs_3" class="obstacle" type="box" pos="5 5 5" size="0.05 0.05 0.05"/>
    <geom name="obs_4" class="obstacle" type="box" pos="5 5 5" size="0.05 0.05 0.05"/>
    <geom name="obs_5" class="obstacle" type="box" pos="5 5 5" size="0.05 0.05 0.05"/>
    <geom name="obs_6" class="obstacle" type="box" pos="5 5 5" size="0.05 0.05 0.05"/>
    <geom name="obs_7" class="obstacle" type="box" pos="5 5 5" size="0.05 0.05 0.05"/>
  </worldbody>

  <actuator>
    <general class="panda" name="actuator1" joint="joint1" gainprm="4500" biasprm="0 -4500 -450"/>
    <general class="panda" name="actuator2" joint="joint2" gainprm="4500" biasprm="0 -4500 -450" ctrlrange="-1.7628 1.7628"/>
    <general class="panda" name="actuator3" joint="joint3" gainprm="3500" biasprm="0 -3500 -350"/>
    <general class="panda" name="actuator4" joint="joint4" gainprm="3500" biasprm="0 -3500 -350" ctrlrange="-3.0718 -0.0698"/>
    <general class="panda" name="actuator5" joint="joint5" gainprm="2000" biasprm="0 -2000 -200" forcerange="-12 12"/>
    <general class="panda" name="actuator6" joint="joint6" gainprm="2000" biasprm="0 -2000 -200" forcerange="-12 12" ctrlrange="-0.0175 3.7525"/>
    <general class="panda" name="actuator7" joint="joint7" gainprm="2000" biasprm="0 -2000 -200" forcerange="-12 12"/>
  </actuator>

  <contact>
    <exclude body1="link0" body2="link1"/>
  </contact>
</mujoco>
